Workbook

Sheet Shariah
F1: =iferror(Sheet1!B4,"") -> Mindteck (India) Ltd
B3: Stock Code | D3: mindteck | F3: =IFERROR("Cmp: "& Sheet1!B3,"") -> Cmp: 178 | H3: =IFERROR("Industry : "& Sheet1!H84,"") | N3: =IFERROR("Sector : "& Sheet1!H85,"") -> Sector : Information Technology
B5: Market Cap | D5: =IFERROR( int(Sheet1!F79),"") -> 543 | F5: =if(D3<>"", IFERROR("Business : "& Sheet1!G92,""),"") -> Business : Pass | H5: =IFERROR("Business Overview : "& char(10) &Sheet1!H86,"") -> Business Overview : Incorporated in 1991, Mindteck Ltd is in the business of rendering engineering and IT services
B7: Non-Sharia Income | D7: =IF(Sheet1!G92="Fail","",iferror(Sheet1!G7,"")) -> 1.7199017 | F7: =iferror(IF(Sheet1!G92="Fail","",Sheet1!H7),"") -> Pass
B9: Debt/Total Assets | D9: =IF(Sheet1!G92="Fail","",iferror(Sheet1!E68,"")) -> 1.0810811 | F9: =iferror(IF(Sheet1!G92="Fail","",Sheet1!F68),"") -> Pass
B11: Illiquidit Assets | D11: =IF(Sheet1!G92="Fail","",iferror(Sheet1!E71,"")) -> 8.9189189 | F11: =iferror(IF(Sheet1!G92="Fail","",Sheet1!F71),"") -> Fail
B13: Liquid Assets | F13: =iferror(IF(Sheet1!G92="Fail","",Sheet1!H78),"") -> Pass
B15: Inventories | F15: =IFERROR("Stock Shariah Status : "& Sheet1!G93,"") -> Stock Shariah Status : Non-Compliant
H17: =iferror(Data!F4,"")
B20: Manual Shariah Calculator:
B21: Non-Sharia Income | D21: =iferror(SUM(D23,D25,D27,D29)/D31*100,"") | F21: Debt/Total Assets | H21: =iferror(((H23+H25)-H27)/H29*100,"") | J21: Illiquid Asset Ratio | L21: =iferror(SUM(L23,L25,L27,L29,L31)/H29*100,"") | N21: Liquid Asset to Mcap | P21: =if(H29-SUM(L23,L25,L27,L29,L31)-P23=0,"",IFERROR(H29-SUM(L23,L25,L27,L29,L31)-P23,"")) | R21: Profit/Divident
B23: from Non-sharia Sales | F23: Non-current borrowing | J23: Property, Plant & Equipment | N23: Total Liabilities | R23: =if(Sheet1!G93<> "Compliant","",iferror(if(AND(T25<>"",T21<>""),("Donate Divident/Profit Rs."&int(T25%*T21)),""),""))
B25: Interest Income | F25: Current borrowing | J25: CWIP | T25: =IF(D21<>"",D21,D7) -> 1.7199017
B27: Any other Investment | F27: Non-Interest loan | I27: ` | J27: Inventories | N27: *Calculations are based on the Fatwa of Mufti Taqi Usmani. **Please perform your own calculations in the part below before making any decisions as the findings from the above section's auto calculation may not be accurate. Donate as much as you can to the needy!
B29: Any Non-Sharia Income | F29: Total Assets | J29: Intangible Assets
B31: Total Sales/Revenue | J31: Right of use/goodwill

Sheet Sheet19

Sheet Sheet1
A1: =Shariah!D3 -> mindteck | C1: //*[@id="top-ratios"]/li[2]/span[2]/span | F1: //*[@id="top"]/div[1]/div/h1
A2: inventory | B2: =Shariah!D15
A3: cmp | B3: =IFERROR(__xludf.DUMMYFUNCTION("IMPORTXML(B5,C1)"),178.0) -> 178
A4: name | B4: =IFERROR(__xludf.DUMMYFUNCTION("IMPORTXML(B5,F1)"),"Mindteck (India) Ltd") -> Mindteck (India) Ltd
A5: ="https://www.screener.in/company/"&A1&"/consolidated/" -> https://www.screener.in/company/mindteck/consolidated/ | B5: ="https://www.screener.in/company/"&A1&"/" -> https://www.screener.in/company/mindteck/
A6: date | B6: {=INDEX(11:11, 1, MAX(IF(11:11<>"", COLUMN(11:11)-1, 0)))} -> Mar 2026 | C6: {=trim(INDEX(11:11, 1, MAX(IF(11:11<>"", COLUMN(11:11), 0))))} -> TTM | D6: Final value | E6: Interest or Other | F6: Ratio
A7: Other Income | B7: {=INDEX(INDIRECT(D10 & ":" & D10), 1, MAX(IF(INDIRECT(D10 & ":" & D10)<>"", COLUMN(INDIRECT(D10 & ":" & D10))-1, 0)))} -> 7 | C7: {=INDEX(INDIRECT(D10 & ":" & D10), 1, MAX(IF(INDIRECT(D10 & ":" & D10)<>"", COLUMN(INDIRECT(D10 & ":" & D10)), 0)))} -> 7 | D7: =IF($C$6="TTM", B7,C7) -> 7 | E7: =IF(D7<=0,D8,D7) -> 7 | F7: =E7/D9*100 -> 1.7199017 | G7: =IF(ISERROR(F7),F26,F7) -> 1.7199017 | H7: =if(G7<=5, "Pass","Fail") -> Pass
A8: Interest | B8: {=INDEX(INDIRECT(C10 & ":" & C10), 1, MAX(IF(INDIRECT(C10 & ":" & C10)<>"", COLUMN(INDIRECT(C10 & ":" & C10))-1, 0)))} -> 1 | C8: {=INDEX(INDIRECT(C10 & ":" & C10), 1, MAX(IF(INDIRECT(C10 & ":" & C10)<>"", COLUMN(INDIRECT(C10 & ":" & C10)), 0)))} -> 1 | D8: =IF($C$6="TTM", B8,C8) -> 1
A9: Sales | B9: {=INDEX(INDIRECT(B10 & ":" & B10), 1, MAX(IF(INDIRECT(B10 & ":" & B10)<>"", COLUMN(INDIRECT(B10 & ":" & B10))-1, 0)))} -> 407 | C9: {=INDEX(INDIRECT(B10 & ":" & B10), 1, MAX(IF(INDIRECT(B10 & ":" & B10)<>"", COLUMN(INDIRECT(B10 & ":" & B10)), 0)))} -> 410 | D9: =IF($C$6="TTM", B9,C9) -> 407
A10: row number | B10: =iferror(row()+match("Sales +",A12:A23, 0)+1,E10) -> 12 | C10: =row()+match("Interest",A12:A23, 0)+1 -> 17 | D10: =row()+match("Other Income +",A12:A23, 0)+1 -> 16 | E10: =row()+match("Revenue",A12:A23, 0)+1 -> #N/A
A11: =IFERROR(__xludf.DUMMYFUNCTION("query(IMPORTHTML($A$5,""table"",2),""SELECT *"",1)"),"") | B11: =IFERROR(__xludf.DUMMYFUNCTION("""COMPUTED_VALUE"""),"Mar 2015") -> Mar 2015 | C11: =IFERROR(__xludf.DUMMYFUNCTION("""COMPUTED_VALUE"""),"Mar 2016") -> Mar 2016 | D11: =IFERROR(__xludf.DUMMYFUNCTION("""COMPUTED_VALUE"""),"Mar 2017") -> Mar 2017 | E11: =IFERROR(__xludf.DUMMYFUNCTION("""COMPUTED_VALUE"""),"Mar 2018") -> Mar 2018 | F11: =IFERROR(__xludf.DUMMYFUNCTION("""COMPUTED_VALUE"""),"Mar 2019") -> Mar 2019 | G11: =IFERROR(__xludf.DUMMYFUNCTION("""COMPUTED_VALUE"""),"Mar 2020") -> Mar 2020 | H11: =IFERROR(__xludf.DUMMYFUNCTION("""COMPUTED_VALUE"""),"Mar 2021") -> Mar 2021 | I11: =IFERROR(__xludf.DUMMYFUNCTION("""COMPUTED_VALUE"""),"Mar 2022") -> Mar 2022 | J11: =IFERROR(__xludf.DUMMYFUNCTION("""COMPUTED_VALUE"""),"Mar 2023") -> Mar 2023 | K11: =IFERROR(__xludf.DUMMYFUNCTION("""COMPUTED_VALUE"""),"Mar 2024") -> Mar 2024 | L11: =IFERROR(__xludf.DUMMYFUNCTION("""COMPUTED_VALUE"""),"Mar 2025") -> Mar 2025 | M11: =IFERROR(__xludf.DUMMYFUNCTION("""COMPUTED_VALUE"""),"Mar 2026") -> Mar 2026 | N11: =IFERROR(__xludf.DUMMYFUNCTION("""COMPUTED_VALUE"""),"TTM") -> TTM
A12: =IFERROR(__xludf.DUMMYFUNCTION("""COMPUTED_VALUE"""),"Sales +") -> Sales + | B12: =IFERROR(__xludf.DUMMYFUNCTION("""COMPUTED_VALUE"""),319.0) -> 319 | C12: =IFERROR(__xludf.DUMMYFUNCTION("""COMPUTED_VALUE"""),312.0) -> 312 | D12: =IFERROR(__xludf.DUMMYFUNCTION("""COMPUTED_VALUE"""),342.0) -> 342 | E12: =IFERROR(__xludf.DUMMYFUNCTION("""COMPUTED_VALUE"""),297.0) -> 297 | F12: =IFERROR(__xludf.DUMMYFUNCTION("""COMPUTED_VALUE"""),299.0) -> 299 | G12: =IFERROR(__xludf.DUMMYFUNCTION("""COMPUTED_VALUE"""),276.0) -> 276 | H12: =IFERROR(__xludf.DUMMYFUNCTION("""COMPUTED_VALUE"""),287.0) -> 287 | I12: =IFERROR(__xludf.DUMMYFUNCTION("""COMPUTED_VALUE"""),299.0) -> 299 | J12: =IFERROR(__xludf.DUMMYFUNCTION("""COMPUTED_VALUE"""),337.0) -> 337 | K12: =IFERROR(__xludf.DUMMYFUNCTION("""COMPUTED_VALUE"""),386.0) -> 386 | L12: =IFERROR(__xludf.DUMMYFUNCTION("""COMPUTED_VALUE"""),424.0) -> 424 | M12: =IFERROR(__xludf.DUMMYFUNCTION("""COMPUTED_VALUE"""),407.0) -> 407 | N12: =IFERROR(__xludf.DUMMYFUNCTION("""COMPUTED_VALUE"""),410.0) -> 410
A13: =IFERROR(__xludf.DUMMYFUNCTION("""COMPUTED_VALUE"""),"Expenses +") -> Expenses + | B13: =IFERROR(__xludf.DUMMYFUNCTION("""COMPUTED_VALUE"""),290.0) -> 290 | C13: =IFERROR(__xludf.DUMMYFUNCTION("""COMPUTED_VALUE"""),291.0) -> 291 | D13: =IFERROR(__xludf.DUMMYFUNCTION("""COMPUTED_VALUE"""),331.0) -> 331 | E13: =IFERROR(__xludf.DUMMYFUNCTION("""COMPUTED_VALUE"""),296.0) -> 296 | F13: =IFERROR(__xludf.DUMMYFUNCTION("""COMPUTED_VALUE"""),295.0) -> 295 | G13: =IFERROR(__xludf.DUMMYFUNCTION("""COMPUTED_VALUE"""),272.0) -> 272 | H13: =IFERROR(__xludf.DUMMYFUNCTION("""COMPUTED_VALUE"""),267.0) -> 267 | I13: =IFERROR(__xludf.DUMMYFUNCTION("""COMPUTED_VALUE"""),278.0) -> 278 | J13: =IFERROR(__xludf.DUMMYFUNCTION("""COMPUTED_VALUE"""),310.0) -> 310 | K13: =IFERROR(__xludf.DUMMYFUNCTION("""COMPUTED_VALUE"""),353.0) -> 353 | L13: =IFERROR(__xludf.DUMMYFUNCTION("""COMPUTED_VALUE"""),389.0) -> 389 | M13: =IFERROR(__xludf.DUMMYFUNCTION("""COMPUTED_VALUE"""),369.0) -> 369 | N13: =IFERROR(__xludf.DUMMYFUNCTION("""COMPUTED_VALUE"""),374.0) -> 374
A14: =IFERROR(__xludf.DUMMYFUNCTION("""COMPUTED_VALUE"""),"Operating Profit") -> Operating Profit | B14: =IFERROR(__xludf.DUMMYFUNCTION("""COMPUTED_VALUE"""),29.0) -> 29 | C14: =IFERROR(__xludf.DUMMYFUNCTION("""COMPUTED_VALUE"""),21.0) -> 21 | D14: =IFERROR(__xludf.DUMMYFUNCTION("""COMPUTED_VALUE"""),11.0) -> 11 | E14: =IFERROR(__xludf.DUMMYFUNCTION("""COMPUTED_VALUE"""),1.0) -> 1 | F14: =IFERROR(__xludf.DUMMYFUNCTION("""COMPUTED_VALUE"""),4.0) -> 4 | G14: =IFERROR(__xludf.DUMMYFUNCTION("""COMPUTED_VALUE"""),4.0) -> 4 | H14: =IFERROR(__xludf.DUMMYFUNCTION("""COMPUTED_VALUE"""),20.0) -> 20 | I14: =IFERROR(__xludf.DUMMYFUNCTION("""COMPUTED_VALUE"""),21.0) -> 21 | J14: =IFERROR(__xludf.DUMMYFUNCTION("""COMPUTED_VALUE"""),27.0) -> 27 | K14: =IFERROR(__xludf.DUMMYFUNCTION("""COMPUTED_VALUE"""),32.0) -> 32 | L14: =IFERROR(__xludf.DUMMYFUNCTION("""COMPUTED_VALUE"""),35.0) -> 35 | M14: =IFERROR(__xludf.DUMMYFUNCTION("""COMPUTED_VALUE"""),38.0) -> 38 | N14: =IFERROR(__xludf.DUMMYFUNCTION("""COMPUTED_VALUE"""),36.0) -> 36
A15: =IFERROR(__xludf.DUMMYFUNCTION("""COMPUTED_VALUE"""),"OPM %") -> OPM % | B15: =IFERROR(__xludf.DUMMYFUNCTION("""COMPUTED_VALUE"""),0.09) -> 0.09 | C15: =IFERROR(__xludf.DUMMYFUNCTION("""COMPUTED_VALUE"""),0.07) -> 0.07 | D15: =IFERROR(__xludf.DUMMYFUNCTION("""COMPUTED_VALUE"""),0.032) -> 0.032 | E15: =IFERROR(__xludf.DUMMYFUNCTION("""COMPUTED_VALUE"""),0.004) -> 0.004 | F15: =IFERROR(__xludf.DUMMYFUNCTION("""COMPUTED_VALUE"""),0.015) -> 0.015 | G15: =IFERROR(__xludf.DUMMYFUNCTION("""COMPUTED_VALUE"""),0.016) -> 0.016 | H15: =IFERROR(__xludf.DUMMYFUNCTION("""COMPUTED_VALUE"""),0.07) -> 0.07 | I15: =IFERROR(__xludf.DUMMYFUNCTION("""COMPUTED_VALUE"""),0.07) -> 0.07 | J15: =IFERROR(__xludf.DUMMYFUNCTION("""COMPUTED_VALUE"""),0.08) -> 0.08 | K15: =IFERROR(__xludf.DUMMYFUNCTION("""COMPUTED_VALUE"""),0.08) -> 0.08 | L15: =IFERROR(__xludf.DUMMYFUNCTION("""COMPUTED_VALUE"""),0.08) -> 0.08 | M15: =IFERROR(__xludf.DUMMYFUNCTION("""COMPUTED_VALUE"""),0.09) -> 0.09 | N15: =IFERROR(__xludf.DUMMYFUNCTION("""COMPUTED_VALUE"""),0.09) -> 0.09
A16: =IFERROR(__xludf.DUMMYFUNCTION("""COMPUTED_VALUE"""),"Other Income +") -> Other Income + | B16: =IFERROR(__xludf.DUMMYFUNCTION("""COMPUTED_VALUE"""),1.0) -> 1 | C16: =IFERROR(__xludf.DUMMYFUNCTION("""COMPUTED_VALUE"""),2.0) -> 2 | D16: =IFERROR(__xludf.DUMMYFUNCTION("""COMPUTED_VALUE"""),3.0) -> 3 | E16: =IFERROR(__xludf.DUMMYFUNCTION("""COMPUTED_VALUE"""),0.0) -> 0 | F16: =IFERROR(__xludf.DUMMYFUNCTION("""COMPUTED_VALUE"""),3.0) -> 3 | G16: =IFERROR(__xludf.DUMMYFUNCTION("""COMPUTED_VALUE"""),-59.0) -> -59 | H16: =IFERROR(__xludf.DUMMYFUNCTION("""COMPUTED_VALUE"""),5.0) -> 5 | I16: =IFERROR(__xludf.DUMMYFUNCTION("""COMPUTED_VALUE"""),23.0) -> 23 | J16: =IFERROR(__xludf.DUMMYFUNCTION("""COMPUTED_VALUE"""),4.0) -> 4 | K16: =IFERROR(__xludf.DUMMYFUNCTION("""COMPUTED_VALUE"""),6.0) -> 6 | L16: =IFERROR(__xludf.DUMMYFUNCTION("""COMPUTED_VALUE"""),6.0) -> 6 | M16: =IFERROR(__xludf.DUMMYFUNCTION("""COMPUTED_VALUE"""),7.0) -> 7 | N16: =IFERROR(__xludf.DUMMYFUNCTION("""COMPUTED_VALUE"""),7.0) -> 7
A17: =IFERROR(__xludf.DUMMYFUNCTION("""COMPUTED_VALUE"""),"Interest") -> Interest | B17: =IFERROR(__xludf.DUMMYFUNCTION("""COMPUTED_VALUE"""),0.0) -> 0 | C17: =IFERROR(__xludf.DUMMYFUNCTION("""COMPUTED_VALUE"""),0.0) -> 0 | D17: =IFERROR(__xludf.DUMMYFUNCTION("""COMPUTED_VALUE"""),0.0) -> 0 | E17: =IFERROR(__xludf.DUMMYFUNCTION("""COMPUTED_VALUE"""),1.0) -> 1 | F17: =IFERROR(__xludf.DUMMYFUNCTION("""COMPUTED_VALUE"""),1.0) -> 1 | G17: =IFERROR(__xludf.DUMMYFUNCTION("""COMPUTED_VALUE"""),2.0) -> 2 | H17: =IFERROR(__xludf.DUMMYFUNCTION("""COMPUTED_VALUE"""),2.0) -> 2 | I17: =IFERROR(__xludf.DUMMYFUNCTION("""COMPUTED_VALUE"""),1.0) -> 1 | J17: =IFERROR(__xludf.DUMMYFUNCTION("""COMPUTED_VALUE"""),1.0) -> 1 | K17: =IFERROR(__xludf.DUMMYFUNCTION("""COMPUTED_VALUE"""),1.0) -> 1 | L17: =IFERROR(__xludf.DUMMYFUNCTION("""COMPUTED_VALUE"""),1.0) -> 1 | M17: =IFERROR(__xludf.DUMMYFUNCTION("""COMPUTED_VALUE"""),1.0) -> 1 | N17: =IFERROR(__xludf.DUMMYFUNCTION("""COMPUTED_VALUE"""),1.0) -> 1
A18: =IFERROR(__xludf.DUMMYFUNCTION("""COMPUTED_VALUE"""),"Depreciation") -> Depreciation | B18: =IFERROR(__xludf.DUMMYFUNCTION("""COMPUTED_VALUE"""),2.0) -> 2 | C18: =IFERROR(__xludf.DUMMYFUNCTION("""COMPUTED_VALUE"""),2.0) -> 2 | D18: =IFERROR(__xludf.DUMMYFUNCTION("""COMPUTED_VALUE"""),2.0) -> 2 | E18: =IFERROR(__xludf.DUMMYFUNCTION("""COMPUTED_VALUE"""),1.0) -> 1 | F18: =IFERROR(__xludf.DUMMYFUNCTION("""COMPUTED_VALUE"""),2.0) -> 2 | G18: =IFERROR(__xludf.DUMMYFUNCTION("""COMPUTED_VALUE"""),7.0) -> 7 | H18: =IFERROR(__xludf.DUMMYFUNCTION("""COMPUTED_VALUE"""),6.0) -> 6 | I18: =IFERROR(__xludf.DUMMYFUNCTION("""COMPUTED_VALUE"""),5.0) -> 5 | J18: =IFERROR(__xludf.DUMMYFUNCTION("""COMPUTED_VALUE"""),5.0) -> 5 | K18: =IFERROR(__xludf.DUMMYFUNCTION("""COMPUTED_VALUE"""),4.0) -> 4 | L18: =IFERROR(__xludf.DUMMYFUNCTION("""COMPUTED_VALUE"""),5.0) -> 5 | M18: =IFERROR(__xludf.DUMMYFUNCTION("""COMPUTED_VALUE"""),5.0) -> 5 | N18: =IFERROR(__xludf.DUMMYFUNCTION("""COMPUTED_VALUE"""),5.0) -> 5
A19: =IFERROR(__xludf.DUMMYFUNCTION("""COMPUTED_VALUE"""),"Profit before tax") -> Profit before tax | B19: =IFERROR(__xludf.DUMMYFUNCTION("""COMPUTED_VALUE"""),28.0) -> 28 | C19: =IFERROR(__xludf.DUMMYFUNCTION("""COMPUTED_VALUE"""),21.0) -> 21 | D19: =IFERROR(__xludf.DUMMYFUNCTION("""COMPUTED_VALUE"""),11.0) -> 11 | E19: =IFERROR(__xludf.DUMMYFUNCTION("""COMPUTED_VALUE"""),0.0) -> 0 | F19: =IFERROR(__xludf.DUMMYFUNCTION("""COMPUTED_VALUE"""),4.0) -> 4 | G19: =IFERROR(__xludf.DUMMYFUNCTION("""COMPUTED_VALUE"""),-64.0) -> -64 | H19: =IFERROR(__xludf.DUMMYFUNCTION("""COMPUTED_VALUE"""),16.0) -> 16 | I19: =IFERROR(__xludf.DUMMYFUNCTION("""COMPUTED_VALUE"""),38.0) -> 38 | J19: =IFERROR(__xludf.DUMMYFUNCTION("""COMPUTED_VALUE"""),26.0) -> 26 | K19: =IFERROR(__xludf.DUMMYFUNCTION("""COMPUTED_VALUE"""),34.0) -> 34 | L19: =IFERROR(__xludf.DUMMYFUNCTION("""COMPUTED_VALUE"""),35.0) -> 35 | M19: =IFERROR(__xludf.DUMMYFUNCTION("""COMPUTED_VALUE"""),39.0) -> 39 | N19: =IFERROR(__xludf.DUMMYFUNCTION("""COMPUTED_VALUE"""),38.0) -> 38
A20: =IFERROR(__xludf.DUMMYFUNCTION("""COMPUTED_VALUE"""),"Tax %") -> Tax % | B20: =IFERROR(__xludf.DUMMYFUNCTION("""COMPUTED_VALUE"""),0.31) -> 0.31 | C20: =IFERROR(__xludf.DUMMYFUNCTION("""COMPUTED_VALUE"""),-0.25) -> -0.25 | D20: =IFERROR(__xludf.DUMMYFUNCTION("""COMPUTED_VALUE"""),0.19) -> 0.19 | E20: =IFERROR(__xludf.DUMMYFUNCTION("""COMPUTED_VALUE"""),46.08) -> 46.08 | F20: =IFERROR(__xludf.DUMMYFUNCTION("""COMPUTED_VALUE"""),0.37) -> 0.37 | G20: =IFERROR(__xludf.DUMMYFUNCTION("""COMPUTED_VALUE"""),0.01) -> 0.01 | H20: =IFERROR(__xludf.DUMMYFUNCTION("""COMPUTED_VALUE"""),0.33) -> 0.33 | I20: =IFERROR(__xludf.DUMMYFUNCTION("""COMPUTED_VALUE"""),0.13) -> 0.13 | J20: =IFERROR(__xludf.DUMMYFUNCTION("""COMPUTED_VALUE"""),0.2) -> 0.2 | K20: =IFERROR(__xludf.DUMMYFUNCTION("""COMPUTED_VALUE"""),0.19) -> 0.19 | L20: =IFERROR(__xludf.DUMMYFUNCTION("""COMPUTED_VALUE"""),0.19) -> 0.19 | M20: =IFERROR(__xludf.DUMMYFUNCTION("""COMPUTED_VALUE"""),0.19) -> 0.19
A21: =IFERROR(__xludf.DUMMYFUNCTION("""COMPUTED_VALUE"""),"Net Profit +") -> Net Profit + | B21: =IFERROR(__xludf.DUMMYFUNCTION("""COMPUTED_VALUE"""),19.0) -> 19 | C21: =IFERROR(__xludf.DUMMYFUNCTION("""COMPUTED_VALUE"""),26.0) -> 26 | D21: =IFERROR(__xludf.DUMMYFUNCTION("""COMPUTED_VALUE"""),9.0) -> 9 | E21: =IFERROR(__xludf.DUMMYFUNCTION("""COMPUTED_VALUE"""),-6.0) -> -6 | F21: =IFERROR(__xludf.DUMMYFUNCTION("""COMPUTED_VALUE"""),3.0) -> 3 | G21: =IFERROR(__xludf.DUMMYFUNCTION("""COMPUTED_VALUE"""),-65.0) -> -65 | H21: =IFERROR(__xludf.DUMMYFUNCTION("""COMPUTED_VALUE"""),11.0) -> 11 | I21: =IFERROR(__xludf.DUMMYFUNCTION("""COMPUTED_VALUE"""),33.0) -> 33 | J21: =IFERROR(__xludf.DUMMYFUNCTION("""COMPUTED_VALUE"""),21.0) -> 21 | K21: =IFERROR(__xludf.DUMMYFUNCTION("""COMPUTED_VALUE"""),27.0) -> 27 | L21: =IFERROR(__xludf.DUMMYFUNCTION("""COMPUTED_VALUE"""),29.0) -> 29 | M21: =IFERROR(__xludf.DUMMYFUNCTION("""COMPUTED_VALUE"""),32.0) -> 32 | N21: =IFERROR(__xludf.DUMMYFUNCTION("""COMPUTED_VALUE"""),31.0) -> 31
A22: =IFERROR(__xludf.DUMMYFUNCTION("""COMPUTED_VALUE"""),"EPS in Rs") -> EPS in Rs | B22: =IFERROR(__xludf.DUMMYFUNCTION("""COMPUTED_VALUE"""),6.13) -> 6.13 | C22: =IFERROR(__xludf.DUMMYFUNCTION("""COMPUTED_VALUE"""),8.23) -> 8.23 | D22: =IFERROR(__xludf.DUMMYFUNCTION("""COMPUTED_VALUE"""),2.93) -> 2.93 | E22: =IFERROR(__xludf.DUMMYFUNCTION("""COMPUTED_VALUE"""),-1.77) -> -1.77 | F22: =IFERROR(__xludf.DUMMYFUNCTION("""COMPUTED_VALUE"""),0.86) -> 0.86 | G22: =IFERROR(__xludf.DUMMYFUNCTION("""COMPUTED_VALUE"""),-20.25) -> -20.25 | H22: =IFERROR(__xludf.DUMMYFUNCTION("""COMPUTED_VALUE"""),3.39) -> 3.39 | I22: =IFERROR(__xludf.DUMMYFUNCTION("""COMPUTED_VALUE"""),10.38) -> 10.38 | J22: =IFERROR(__xludf.DUMMYFUNCTION("""COMPUTED_VALUE"""),6.57) -> 6.57 | K22: =IFERROR(__xludf.DUMMYFUNCTION("""COMPUTED_VALUE"""),8.62) -> 8.62 | L22: =IFERROR(__xludf.DUMMYFUNCTION("""COMPUTED_VALUE"""),8.99) -> 8.99 | M22: =IFERROR(__xludf.DUMMYFUNCTION("""COMPUTED_VALUE"""),9.86) -> 9.86 | N22: =IFERROR(__xludf.DUMMYFUNCTION("""COMPUTED_VALUE"""),9.75) -> 9.75
A23: =IFERROR(__xludf.DUMMYFUNCTION("""COMPUTED_VALUE"""),"Dividend Payout %") -> Dividend Payout % | B23: =IFERROR(__xludf.DUMMYFUNCTION("""COMPUTED_VALUE"""),0.13) -> 0.13 | C23: =IFERROR(__xludf.DUMMYFUNCTION("""COMPUTED_VALUE"""),0.1) -> 0.1 | D23: =IFERROR(__xludf.DUMMYFUNCTION("""COMPUTED_VALUE"""),0.27) -> 0.27 | E23: =IFERROR(__xludf.DUMMYFUNCTION("""COMPUTED_VALUE"""),-0.45) -> -0.45 | F23: =IFERROR(__xludf.DUMMYFUNCTION("""COMPUTED_VALUE"""),0.92) -> 0.92 | G23: =IFERROR(__xludf.DUMMYFUNCTION("""COMPUTED_VALUE"""),0.0) -> 0 | H23: =IFERROR(__xludf.DUMMYFUNCTION("""COMPUTED_VALUE"""),0.0) -> 0 | I23: =IFERROR(__xludf.DUMMYFUNCTION("""COMPUTED_VALUE"""),0.08) -> 0.08 | J23: =IFERROR(__xludf.DUMMYFUNCTION("""COMPUTED_VALUE"""),0.12) -> 0.12 | K23: =IFERROR(__xludf.DUMMYFUNCTION("""COMPUTED_VALUE"""),0.09) -> 0.09 | L23: =IFERROR(__xludf.DUMMYFUNCTION("""COMPUTED_VALUE"""),0.11) -> 0.11 | M23: =IFERROR(__xludf.DUMMYFUNCTION("""COMPUTED_VALUE"""),0.1) -> 0.1
A25: date | B25: {=INDEX(30:30, 1, MAX(IF(30:30<>"", COLUMN(30:30)-1, 0)))} -> Mar 2026 | C25: {=trim(INDEX(30:30, 1, MAX(IF(30:30<>"", COLUMN(30:30), 0))))} -> TTM | D25: Final value | E25: Interest or Other | F25: Ratio
A26: Other Income | B26: {=INDEX(INDIRECT(D29 & ":" & D29), 1, MAX(IF(INDIRECT(D29 & ":" & D29)<>"", COLUMN(INDIRECT(D29 & ":" & D29))-1, 0)))} -> 3 | C26: {=INDEX(INDIRECT(D29 & ":" & D29), 1, MAX(IF(INDIRECT(D29 & ":" & D29)<>"", COLUMN(INDIRECT(D29 & ":" & D29)), 0)))} -> 3 | D26: =IF($C$25="TTM", B26,C26) -> 3 | E26: =IF(D26<=0,D27,D26) -> 3 | F26: =E26/D28*100 -> 2
A27: Interest | B27: {=INDEX(INDIRECT(C29 & ":" & C29), 1, MAX(IF(INDIRECT(C29 & ":" & C29)<>"", COLUMN(INDIRECT(C29 & ":" & C29))-1, 0)))} -> 1 | C27: {=INDEX(INDIRECT(C29 & ":" & C29), 1, MAX(IF(INDIRECT(C29 & ":" & C29)<>"", COLUMN(INDIRECT(C29 & ":" & C29)), 0)))} -> 0 | D27: =IF($C$25="TTM", B27,C27) -> 1
A28: Sales | B28: {=INDEX(INDIRECT(B29 & ":" & B29), 1, MAX(IF(INDIRECT(B29 & ":" & B29)<>"", COLUMN(INDIRECT(B29 & ":" & B29))-1, 0)))} -> 150 | C28: {=INDEX(INDIRECT(B29 & ":" & B29), 1, MAX(IF(INDIRECT(B29 & ":" & B29)<>"", COLUMN(INDIRECT(B29 & ":" & B29)), 0)))} -> 148 | D28: =IF($C$25="TTM", B28,C28) -> 150
B29: =iferror(row()+match("Sales +",A31:A42, 0)+1,E29) -> 31 | C29: =row()+match("Interest",A31:A42, 0)+1 -> 36 | D29: =row()+match("Other Income +",A31:A42, 0)+1 -> 35 | E29: =row()+match("Revenue",A31:A42, 0)+1 -> #N/A
A30: =IFERROR(__xludf.DUMMYFUNCTION("query(IMPORTHTML($B$5,""table"",2),""SELECT *"",1)"),"") | B30: =IFERROR(__xludf.DUMMYFUNCTION("""COMPUTED_VALUE"""),"Mar 2015") -> Mar 2015 | C30: =IFERROR(__xludf.DUMMYFUNCTION("""COMPUTED_VALUE"""),"Mar 2016") -> Mar 2016 | D30: =IFERROR(__xludf.DUMMYFUNCTION("""COMPUTED_VALUE"""),"Mar 2017") -> Mar 2017 | E30: =IFERROR(__xludf.DUMMYFUNCTION("""COMPUTED_VALUE"""),"Mar 2018") -> Mar 2018 | F30: =IFERROR(__xludf.DUMMYFUNCTION("""COMPUTED_VALUE"""),"Mar 2019") -> Mar 2019 | G30: =IFERROR(__xludf.DUMMYFUNCTION("""COMPUTED_VALUE"""),"Mar 2020") -> Mar 2020 | H30: =IFERROR(__xludf.DUMMYFUNCTION("""COMPUTED_VALUE"""),"Mar 2021") -> Mar 2021 | I30: =IFERROR(__xludf.DUMMYFUNCTION("""COMPUTED_VALUE"""),"Mar 2022") -> Mar 2022 | J30: =IFERROR(__xludf.DUMMYFUNCTION("""COMPUTED_VALUE"""),"Mar 2023") -> Mar 2023 | K30: =IFERROR(__xludf.DUMMYFUNCTION("""COMPUTED_VALUE"""),"Mar 2024") -> Mar 2024 | L30: =IFERROR(__xludf.DUMMYFUNCTION("""COMPUTED_VALUE"""),"Mar 2025") -> Mar 2025 | M30: =IFERROR(__xludf.DUMMYFUNCTION("""COMPUTED_VALUE"""),"Mar 2026") -> Mar 2026 | N30: =IFERROR(__xludf.DUMMYFUNCTION("""COMPUTED_VALUE"""),"TTM") -> TTM
A31: =IFERROR(__xludf.DUMMYFUNCTION("""COMPUTED_VALUE"""),"Sales +") -> Sales + | B31: =IFERROR(__xludf.DUMMYFUNCTION("""COMPUTED_VALUE"""),80.0) -> 80 | C31: =IFERROR(__xludf.DUMMYFUNCTION("""COMPUTED_VALUE"""),87.0) -> 87 | D31: =IFERROR(__xludf.DUMMYFUNCTION("""COMPUTED_VALUE"""),84.0) -> 84 | E31: =IFERROR(__xludf.DUMMYFUNCTION("""COMPUTED_VALUE"""),88.0) -> 88 | F31: =IFERROR(__xludf.DUMMYFUNCTION("""COMPUTED_VALUE"""),108.0) -> 108 | G31: =IFERROR(__xludf.DUMMYFUNCTION("""COMPUTED_VALUE"""),92.0) -> 92 | H31: =IFERROR(__xludf.DUMMYFUNCTION("""COMPUTED_VALUE"""),104.0) -> 104 | I31: =IFERROR(__xludf.DUMMYFUNCTION("""COMPUTED_VALUE"""),114.0) -> 114 | J31: =IFERROR(__xludf.DUMMYFUNCTION("""COMPUTED_VALUE"""),130.0) -> 130 | K31: =IFERROR(__xludf.DUMMYFUNCTION("""COMPUTED_VALUE"""),140.0) -> 140 | L31: =IFERROR(__xludf.DUMMYFUNCTION("""COMPUTED_VALUE"""),155.0) -> 155 | M31: =IFERROR(__xludf.DUMMYFUNCTION("""COMPUTED_VALUE"""),150.0) -> 150 | N31: =IFERROR(__xludf.DUMMYFUNCTION("""COMPUTED_VALUE"""),148.0) -> 148
A32: =IFERROR(__xludf.DUMMYFUNCTION("""COMPUTED_VALUE"""),"Expenses +") -> Expenses + | B32: =IFERROR(__xludf.DUMMYFUNCTION("""COMPUTED_VALUE"""),62.0) -> 62 | C32: =IFERROR(__xludf.DUMMYFUNCTION("""COMPUTED_VALUE"""),74.0) -> 74 | D32: =IFERROR(__xludf.DUMMYFUNCTION("""COMPUTED_VALUE"""),78.0) -> 78 | E32: =IFERROR(__xludf.DUMMYFUNCTION("""COMPUTED_VALUE"""),85.0) -> 85 | F32: =IFERROR(__xludf.DUMMYFUNCTION("""COMPUTED_VALUE"""),97.0) -> 97 | G32: =IFERROR(__xludf.DUMMYFUNCTION("""COMPUTED_VALUE"""),85.0) -> 85 | H32: =IFERROR(__xludf.DUMMYFUNCTION("""COMPUTED_VALUE"""),86.0) -> 86 | I32: =IFERROR(__xludf.DUMMYFUNCTION("""COMPUTED_VALUE"""),98.0) -> 98 | J32: =IFERROR(__xludf.DUMMYFUNCTION("""COMPUTED_VALUE"""),109.0) -> 109 | K32: =IFERROR(__xludf.DUMMYFUNCTION("""COMPUTED_VALUE"""),118.0) -> 118 | L32: =IFERROR(__xludf.DUMMYFUNCTION("""COMPUTED_VALUE"""),131.0) -> 131 | M32: =IFERROR(__xludf.DUMMYFUNCTION("""COMPUTED_VALUE"""),124.0) -> 124 | N32: =IFERROR(__xludf.DUMMYFUNCTION("""COMPUTED_VALUE"""),124.0) -> 124
A33: =IFERROR(__xludf.DUMMYFUNCTION("""COMPUTED_VALUE"""),"Operating Profit") -> Operating Profit | B33: =IFERROR(__xludf.DUMMYFUNCTION("""COMPUTED_VALUE"""),19.0) -> 19 | C33: =IFERROR(__xludf.DUMMYFUNCTION("""COMPUTED_VALUE"""),13.0) -> 13 | D33: =IFERROR(__xludf.DUMMYFUNCTION("""COMPUTED_VALUE"""),6.0) -> 6 | E33: =IFERROR(__xludf.DUMMYFUNCTION("""COMPUTED_VALUE"""),4.0) -> 4 | F33: =IFERROR(__xludf.DUMMYFUNCTION("""COMPUTED_VALUE"""),10.0) -> 10 | G33: =IFERROR(__xludf.DUMMYFUNCTION("""COMPUTED_VALUE"""),7.0) -> 7 | H33: =IFERROR(__xludf.DUMMYFUNCTION("""COMPUTED_VALUE"""),18.0) -> 18 | I33: =IFERROR(__xludf.DUMMYFUNCTION("""COMPUTED_VALUE"""),17.0) -> 17 | J33: =IFERROR(__xludf.DUMMYFUNCTION("""COMPUTED_VALUE"""),21.0) -> 21 | K33: =IFERROR(__xludf.DUMMYFUNCTION("""COMPUTED_VALUE"""),22.0) -> 22 | L33: =IFERROR(__xludf.DUMMYFUNCTION("""COMPUTED_VALUE"""),25.0) -> 25 | M33: =IFERROR(__xludf.DUMMYFUNCTION("""COMPUTED_VALUE"""),25.0) -> 25 | N33: =IFERROR(__xludf.DUMMYFUNCTION("""COMPUTED_VALUE"""),25.0) -> 25
A34: =IFERROR(__xludf.DUMMYFUNCTION("""COMPUTED_VALUE"""),"OPM %") -> OPM % | B34: =IFERROR(__xludf.DUMMYFUNCTION("""COMPUTED_VALUE"""),0.23) -> 0.23 | C34: =IFERROR(__xludf.DUMMYFUNCTION("""COMPUTED_VALUE"""),0.15) -> 0.15 | D34: =IFERROR(__xludf.DUMMYFUNCTION("""COMPUTED_VALUE"""),0.07) -> 0.07 | E34: =IFERROR(__xludf.DUMMYFUNCTION("""COMPUTED_VALUE"""),0.042) -> 0.042 | F34: =IFERROR(__xludf.DUMMYFUNCTION("""COMPUTED_VALUE"""),0.09) -> 0.09 | G34: =IFERROR(__xludf.DUMMYFUNCTION("""COMPUTED_VALUE"""),0.08) -> 0.08 | H34: =IFERROR(__xludf.DUMMYFUNCTION("""COMPUTED_VALUE"""),0.18) -> 0.18 | I34: =IFERROR(__xludf.DUMMYFUNCTION("""COMPUTED_VALUE"""),0.15) -> 0.15 | J34: =IFERROR(__xludf.DUMMYFUNCTION("""COMPUTED_VALUE"""),0.16) -> 0.16 | K34: =IFERROR(__xludf.DUMMYFUNCTION("""COMPUTED_VALUE"""),0.16) -> 0.16 | L34: =IFERROR(__xludf.DUMMYFUNCTION("""COMPUTED_VALUE"""),0.16) -> 0.16 | M34: =IFERROR(__xludf.DUMMYFUNCTION("""COMPUTED_VALUE"""),0.17) -> 0.17 | N34: =IFERROR(__xludf.DUMMYFUNCTION("""COMPUTED_VALUE"""),0.17) -> 0.17
A35: =IFERROR(__xludf.DUMMYFUNCTION("""COMPUTED_VALUE"""),"Other Income +") -> Other Income + | B35: =IFERROR(__xludf.DUMMYFUNCTION("""COMPUTED_VALUE"""),1.0) -> 1 | C35: =IFERROR(__xludf.DUMMYFUNCTION("""COMPUTED_VALUE"""),2.0) -> 2 | D35: =IFERROR(__xludf.DUMMYFUNCTION("""COMPUTED_VALUE"""),3.0) -> 3 | E35: =IFERROR(__xludf.DUMMYFUNCTION("""COMPUTED_VALUE"""),2.0) -> 2 | F35: =IFERROR(__xludf.DUMMYFUNCTION("""COMPUTED_VALUE"""),2.0) -> 2 | G35: =IFERROR(__xludf.DUMMYFUNCTION("""COMPUTED_VALUE"""),-58.0) -> -58 | H35: =IFERROR(__xludf.DUMMYFUNCTION("""COMPUTED_VALUE"""),3.0) -> 3 | I35: =IFERROR(__xludf.DUMMYFUNCTION("""COMPUTED_VALUE"""),3.0) -> 3 | J35: =IFERROR(__xludf.DUMMYFUNCTION("""COMPUTED_VALUE"""),4.0) -> 4 | K35: =IFERROR(__xludf.DUMMYFUNCTION("""COMPUTED_VALUE"""),7.0) -> 7 | L35: =IFERROR(__xludf.DUMMYFUNCTION("""COMPUTED_VALUE"""),5.0) -> 5 | M35: =IFERROR(__xludf.DUMMYFUNCTION("""COMPUTED_VALUE"""),3.0) -> 3 | N35: =IFERROR(__xludf.DUMMYFUNCTION("""COMPUTED_VALUE"""),3.0) -> 3
A36: =IFERROR(__xludf.DUMMYFUNCTION("""COMPUTED_VALUE"""),"Interest") -> Interest | B36: =IFERROR(__xludf.DUMMYFUNCTION("""COMPUTED_VALUE"""),0.0) -> 0 | C36: =IFERROR(__xludf.DUMMYFUNCTION("""COMPUTED_VALUE"""),0.0) -> 0 | D36: =IFERROR(__xludf.DUMMYFUNCTION("""COMPUTED_VALUE"""),0.0) -> 0 | E36: =IFERROR(__xludf.DUMMYFUNCTION("""COMPUTED_VALUE"""),0.0) -> 0 | F36: =IFERROR(__xludf.DUMMYFUNCTION("""COMPUTED_VALUE"""),1.0) -> 1 | G36: =IFERROR(__xludf.DUMMYFUNCTION("""COMPUTED_VALUE"""),2.0) -> 2 | H36: =IFERROR(__xludf.DUMMYFUNCTION("""COMPUTED_VALUE"""),1.0) -> 1 | I36: =IFERROR(__xludf.DUMMYFUNCTION("""COMPUTED_VALUE"""),0.0) -> 0 | J36: =IFERROR(__xludf.DUMMYFUNCTION("""COMPUTED_VALUE"""),1.0) -> 1 | K36: =IFERROR(__xludf.DUMMYFUNCTION("""COMPUTED_VALUE"""),0.0) -> 0 | L36: =IFERROR(__xludf.DUMMYFUNCTION("""COMPUTED_VALUE"""),1.0) -> 1 | M36: =IFERROR(__xludf.DUMMYFUNCTION("""COMPUTED_VALUE"""),1.0) -> 1 | N36: =IFERROR(__xludf.DUMMYFUNCTION("""COMPUTED_VALUE"""),0.0) -> 0
A37: =IFERROR(__xludf.DUMMYFUNCTION("""COMPUTED_VALUE"""),"Depreciation") -> Depreciation | B37: =IFERROR(__xludf.DUMMYFUNCTION("""COMPUTED_VALUE"""),2.0) -> 2 | C37: =IFERROR(__xludf.DUMMYFUNCTION("""COMPUTED_VALUE"""),2.0) -> 2 | D37: =IFERROR(__xludf.DUMMYFUNCTION("""COMPUTED_VALUE"""),1.0) -> 1 | E37: =IFERROR(__xludf.DUMMYFUNCTION("""COMPUTED_VALUE"""),1.0) -> 1 | F37: =IFERROR(__xludf.DUMMYFUNCTION("""COMPUTED_VALUE"""),2.0) -> 2 | G37: =IFERROR(__xludf.DUMMYFUNCTION("""COMPUTED_VALUE"""),6.0) -> 6 | H37: =IFERROR(__xludf.DUMMYFUNCTION("""COMPUTED_VALUE"""),6.0) -> 6 | I37: =IFERROR(__xludf.DUMMYFUNCTION("""COMPUTED_VALUE"""),5.0) -> 5 | J37: =IFERROR(__xludf.DUMMYFUNCTION("""COMPUTED_VALUE"""),4.0) -> 4 | K37: =IFERROR(__xludf.DUMMYFUNCTION("""COMPUTED_VALUE"""),4.0) -> 4 | L37: =IFERROR(__xludf.DUMMYFUNCTION("""COMPUTED_VALUE"""),5.0) -> 5 | M37: =IFERROR(__xludf.DUMMYFUNCTION("""COMPUTED_VALUE"""),4.0) -> 4 | N37: =IFERROR(__xludf.DUMMYFUNCTION("""COMPUTED_VALUE"""),4.0) -> 4
A38: =IFERROR(__xludf.DUMMYFUNCTION("""COMPUTED_VALUE"""),"Profit before tax") -> Profit before tax | B38: =IFERROR(__xludf.DUMMYFUNCTION("""COMPUTED_VALUE"""),18.0) -> 18 | C38: =IFERROR(__xludf.DUMMYFUNCTION("""COMPUTED_VALUE"""),14.0) -> 14 | D38: =IFERROR(__xludf.DUMMYFUNCTION("""COMPUTED_VALUE"""),7.0) -> 7 | E38: =IFERROR(__xludf.DUMMYFUNCTION("""COMPUTED_VALUE"""),4.0) -> 4 | F38: =IFERROR(__xludf.DUMMYFUNCTION("""COMPUTED_VALUE"""),10.0) -> 10 | G38: =IFERROR(__xludf.DUMMYFUNCTION("""COMPUTED_VALUE"""),-59.0) -> -59 | H38: =IFERROR(__xludf.DUMMYFUNCTION("""COMPUTED_VALUE"""),14.0) -> 14 | I38: =IFERROR(__xludf.DUMMYFUNCTION("""COMPUTED_VALUE"""),15.0) -> 15 | J38: =IFERROR(__xludf.DUMMYFUNCTION("""COMPUTED_VALUE"""),20.0) -> 20 | K38: =IFERROR(__xludf.DUMMYFUNCTION("""COMPUTED_VALUE"""),24.0) -> 24 | L38: =IFERROR(__xludf.DUMMYFUNCTION("""COMPUTED_VALUE"""),25.0) -> 25 | M38: =IFERROR(__xludf.DUMMYFUNCTION("""COMPUTED_VALUE"""),24.0) -> 24 | N38: =IFERROR(__xludf.DUMMYFUNCTION("""COMPUTED_VALUE"""),23.0) -> 23
A39: =IFERROR(__xludf.DUMMYFUNCTION("""COMPUTED_VALUE"""),"Tax %") -> Tax % | B39: =IFERROR(__xludf.DUMMYFUNCTION("""COMPUTED_VALUE"""),0.36) -> 0.36 | C39: =IFERROR(__xludf.DUMMYFUNCTION("""COMPUTED_VALUE"""),0.39) -> 0.39 | D39: =IFERROR(__xludf.DUMMYFUNCTION("""COMPUTED_VALUE"""),0.37) -> 0.37 | E39: =IFERROR(__xludf.DUMMYFUNCTION("""COMPUTED_VALUE"""),0.55) -> 0.55 | F39: =IFERROR(__xludf.DUMMYFUNCTION("""COMPUTED_VALUE"""),0.3) -> 0.3 | G39: =IFERROR(__xludf.DUMMYFUNCTION("""COMPUTED_VALUE"""),0.01) -> 0.01 | H39: =IFERROR(__xludf.DUMMYFUNCTION("""COMPUTED_VALUE"""),0.39) -> 0.39 | I39: =IFERROR(__xludf.DUMMYFUNCTION("""COMPUTED_VALUE"""),0.26) -> 0.26 | J39: =IFERROR(__xludf.DUMMYFUNCTION("""COMPUTED_VALUE"""),0.24) -> 0.24 | K39: =IFERROR(__xludf.DUMMYFUNCTION("""COMPUTED_VALUE"""),0.23) -> 0.23 | L39: =IFERROR(__xludf.DUMMYFUNCTION("""COMPUTED_VALUE"""),0.25) -> 0.25 | M39: =IFERROR(__xludf.DUMMYFUNCTION("""COMPUTED_VALUE"""),0.26) -> 0.26
A40: =IFERROR(__xludf.DUMMYFUNCTION("""COMPUTED_VALUE"""),"Net Profit +") -> Net Profit + | B40: =IFERROR(__xludf.DUMMYFUNCTION("""COMPUTED_VALUE"""),11.0) -> 11 | C40: =IFERROR(__xludf.DUMMYFUNCTION("""COMPUTED_VALUE"""),8.0) -> 8 | D40: =IFERROR(__xludf.DUMMYFUNCTION("""COMPUTED_VALUE"""),4.0) -> 4 | E40: =IFERROR(__xludf.DUMMYFUNCTION("""COMPUTED_VALUE"""),2.0) -> 2 | F40: =IFERROR(__xludf.DUMMYFUNCTION("""COMPUTED_VALUE"""),7.0) -> 7 | G40: =IFERROR(__xludf.DUMMYFUNCTION("""COMPUTED_VALUE"""),-59.0) -> -59 | H40: =IFERROR(__xludf.DUMMYFUNCTION("""COMPUTED_VALUE"""),9.0) -> 9 | I40: =IFERROR(__xludf.DUMMYFUNCTION("""COMPUTED_VALUE"""),11.0) -> 11 | J40: =IFERROR(__xludf.DUMMYFUNCTION("""COMPUTED_VALUE"""),15.0) -> 15 | K40: =IFERROR(__xludf.DUMMYFUNCTION("""COMPUTED_VALUE"""),18.0) -> 18 | L40: =IFERROR(__xludf.DUMMYFUNCTION("""COMPUTED_VALUE"""),19.0) -> 19 | M40: =IFERROR(__xludf.DUMMYFUNCTION("""COMPUTED_VALUE"""),17.0) -> 17 | N40: =IFERROR(__xludf.DUMMYFUNCTION("""COMPUTED_VALUE"""),17.0) -> 17
A41: =IFERROR(__xludf.DUMMYFUNCTION("""COMPUTED_VALUE"""),"EPS in Rs") -> EPS in Rs | B41: =IFERROR(__xludf.DUMMYFUNCTION("""COMPUTED_VALUE"""),3.67) -> 3.67 | C41: =IFERROR(__xludf.DUMMYFUNCTION("""COMPUTED_VALUE"""),2.6) -> 2.6 | D41: =IFERROR(__xludf.DUMMYFUNCTION("""COMPUTED_VALUE"""),1.39) -> 1.39 | E41: =IFERROR(__xludf.DUMMYFUNCTION("""COMPUTED_VALUE"""),0.6) -> 0.6 | F41: =IFERROR(__xludf.DUMMYFUNCTION("""COMPUTED_VALUE"""),2.25) -> 2.25 | G41: =IFERROR(__xludf.DUMMYFUNCTION("""COMPUTED_VALUE"""),-18.51) -> -18.51 | H41: =IFERROR(__xludf.DUMMYFUNCTION("""COMPUTED_VALUE"""),2.67) -> 2.67 | I41: =IFERROR(__xludf.DUMMYFUNCTION("""COMPUTED_VALUE"""),3.42) -> 3.42 | J41: =IFERROR(__xludf.DUMMYFUNCTION("""COMPUTED_VALUE"""),4.71) -> 4.71 | K41: =IFERROR(__xludf.DUMMYFUNCTION("""COMPUTED_VALUE"""),5.76) -> 5.76 | L41: =IFERROR(__xludf.DUMMYFUNCTION("""COMPUTED_VALUE"""),5.9) -> 5.9 | M41: =IFERROR(__xludf.DUMMYFUNCTION("""COMPUTED_VALUE"""),5.45) -> 5.45 | N41: =IFERROR(__xludf.DUMMYFUNCTION("""COMPUTED_VALUE"""),5.18) -> 5.18
...

Sheet list
A1: Stock list | B1: Non-Shariah Business | E1: RELIANCE
A2: agi | B2: wine bottle manufacturer | E2: TCS
A3: atulauto | B3: Finance & banking Income | E3: HDFCBANK
A4: 526187 | B4: ritual/religious | C4: ashram | E4: ICICIBANK
A5: prajind | B5: wine factory maker | E5: HINDUNILVR
A6: GULPOLY | B6: Wine raw material provider | E6: INFY
A7: Infy | B7: Finance & banking Income | E7: HDFC
E8: ITC
E9: SBIN
E10: BHARTIARTL
E11: KOTAKBANK
E12: BAJFINANCE
E13: LICI
E14: LT
E15: HCLTECH
E16: ASIANPAINT
E17: AXISBANK
E18: MARUTI
E19: SUNPHARMA
... E2137: ZICOM

Sheet nse stock
A1: Reliance Industries Limited | B1: RELIANCE
A2: Tata Consultancy Services Limited | B2: TCS
A3: HDFC Bank Limited | B3: HDFCBANK
A4: ICICI Bank Limited | B4: ICICIBANK
A5: Hindustan Unilever Limited | B5: HINDUNILVR
A6: Infosys Limited | B6: INFY
A7: Housing Development Finance Corporation Limited | B7: HDFC
A8: ITC Limited | B8: ITC
A9: State Bank of India | B9: SBIN
A10: Bharti Airtel Limited | B10: BHARTIARTL
A11: Kotak Mahindra Bank Limited | B11: KOTAKBANK
A12: Bajaj Finance Limited | B12: BAJFINANCE
... A2137: Zicom Electronic Security Systems Limited | B2137: ZICOM
